{"event": "verbose", "uuid": "d49bb54a-8a2b-49f6-b307-e42b517168c6", "counter": 3, "stdout": "\u001b[0;31mThe error appears to be in '/root/python/Network/ansible/playbooks/roles/hostname/tasks/main.yml': line 3, column 3, but may\u001b[0m", "start_line": 2, "end_line": 3, "runner_ident": "bb521f0e-78f2-4b8f-a34d-2b3ee48f68d3", "created": "2025-01-20T13:59:09.434939+00:00"}