{"event": "verbose", "uuid": "7aa91a75-e3c4-4a69-acad-fab3d17349e5", "counter": 3, "stdout": "\u001b[0;31mThe error appears to be in '/root/python/Network/ansible/playbooks/roles/hostname/tasks/main.yml': line 3, column 3, but may\u001b[0m", "start_line": 2, "end_line": 3, "runner_ident": "f207753a-0626-4dc9-9541-949932e4485a", "created": "2025-01-20T13:54:18.548710+00:00"}