{"event": "verbose", "uuid": "6deeb11a-736e-4e99-86cb-62574f2c3373", "counter": 3, "stdout": "\u001b[0;31mThe error appears to be in '/root/python/Network/ansible/playbooks/roles/ip_config/tasks/main.yml': line 2, column 3, but may\u001b[0m", "start_line": 2, "end_line": 3, "runner_ident": "7fdfa587-a794-4da2-8c29-e1ed740b8868", "created": "2025-01-20T15:15:52.746002+00:00"}